<!-- Look at http://wiki.ros.org/urdf/XML/link -->
<robot name="fifth_robot">
       <link name="base_link">
         <interial>
            <origin xyz="0 0 0.14" rpy="0 0 0" />
            <mass value="1">
            <inertia ixx="100" ixy="0" ixz="0" iyy="1000" iyz="0"  izz="1000"/>
         </interial>
         <visual>
            <origin xyz="0 0 0.14" rpy="0 0 0" />
            <geometry>
               <box size="0.5 0.5 0.5">
            </geometry>
            <material name="Cyan">
               <color rgba="0 1.0 1.0 1.0">
            </material>
         </visual>
         <collision>
            <origin xyz="0 0 0" rpy="0 0 0" />
            <geometry>
               <cylinder radius="0.8" length="0.5">
            </geometry>
         </collision>
       </link>
   <link name="lrf" />
   </link>
   <joint name="joint1" type="continuous">
     <parent link="base_link"/>
     <child link="lrf"/>
   </joint>

</robot>
